import Foundation

enum ConnectionContinuationError: Error {
	case serviceTypeMismatch
	case missingBothValueAndError
}

extension NSXPCConnection {
	/// Begins remote method invocation that returns a value.
	public func withContinuation<Service, Value>(
		function: String = #function,
		on actor: isolated some Actor,
		_ body: (Service, CheckedContinuation<Value, Error>) -> Void
	) async throws -> Value {
		return try await withCheckedThrowingContinuation(function: function) { continuation in
			let proxy = self.remoteObjectProxyWithErrorHandler { error in
				continuation.resume(throwing: error)
			}

			guard let service = proxy as? Service else {
				continuation.resume(throwing: ConnectionContinuationError.serviceTypeMismatch)
				return
			}

			body(service, continuation)
		}
	}

	/// Begins remote method invocation that returns a value.
	@_unsafeInheritExecutor
	public func withContinuation<Service, Value>(
		function: String = #function,
		_ body: (Service, CheckedContinuation<Value, Error>) -> Void
	) async throws -> Value {
		return try await withCheckedThrowingContinuation(function: function) { continuation in
			let proxy = self.remoteObjectProxyWithErrorHandler { error in
				continuation.resume(throwing: error)
			}

			guard let service = proxy as? Service else {
				continuation.resume(throwing: ConnectionContinuationError.serviceTypeMismatch)
				return
			}

			body(service, continuation)
		}
	}

	/// Begins remote method invocation.
	///
	/// Even though the remote call does not return errors, this function still throws because communication can always fail.
	@_unsafeInheritExecutor
	public func withService<Service>(
		function: String = #function,
		_ body: (Service) throws -> Void
	) async throws {
		try await withContinuation(function: function, { (service: Service, continuation: CheckedContinuation<Void, Error>) in
			do {
				try body(service)

				continuation.resume()
			} catch {
				continuation.resume(throwing: error)
			}
		})
	}

	/// Begins remote method invocation.
	///
	/// Even though the remote call does not return errors, this function still throws because communication can always fail.
	public func withService<Service>(
		function: String = #function,
		on actor: isolated some Actor,
		_ body: (Service) throws -> Void
	) async throws {
		try await withContinuation(function: function, on: actor, { (service: Service, continuation: CheckedContinuation<Void, Error>) in
			do {
				try body(service)

				continuation.resume()
			} catch {
				continuation.resume(throwing: error)
			}
		})
	}
}

extension NSXPCConnection {
	/// Begins remote method invocation that calls out to a value-error pair completion handler.
	///
	/// This function always throws if an error is returned from the completion handler.
	@_unsafeInheritExecutor
	public func withValueErrorCompletion<Service, Value: Sendable>(
		function: String = #function,
		_ body: (Service, @escaping @Sendable (Value?, Error?) -> Void) -> Void
	) async throws -> Value {
		try await withContinuation(function: function) { service, continuation in
			body(service) { value, error in
				switch (value, error) {
				case let (value?, nil):
					continuation.resume(returning: value)
				case let (nil, error?):
					continuation.resume(throwing: error)
				case let (_, error?):
					continuation.resume(throwing: error)
				case (nil, nil):
					continuation.resume(throwing: ConnectionContinuationError.missingBothValueAndError)
				}
			}
		}
	}

	/// Begins remote method invocation that calls out to a value-error pair completion handler.
	///
	/// This function always throws if an error is returned from the completion handler.
	public func withValueErrorCompletion<Service, Value: Sendable>(
		function: String = #function,
		on actor: isolated some Actor,
		_ body: (Service, @escaping @Sendable (Value?, Error?) -> Void) -> Void
	) async throws -> Value {
		try await withContinuation(function: function, on: actor) { service, continuation in
			body(service) { value, error in
				switch (value, error) {
				case let (value?, nil):
					continuation.resume(returning: value)
				case let (nil, error?):
					continuation.resume(throwing: error)
				case let (_, error?):
					continuation.resume(throwing: error)
				case (nil, nil):
					continuation.resume(throwing: ConnectionContinuationError.missingBothValueAndError)
				}
			}
		}
	}

	/// Begins remote method invocation that calls out to a Result-based completion handler.
	@_unsafeInheritExecutor
	public func withResultCompletion<Service, Value: Sendable>(
		function: String = #function,
		_ body: (Service, @escaping @Sendable (Result<Value, Error>) -> Void) -> Void
	) async throws -> Value {
		try await withContinuation(function: function) { service, continuation in
			body(service) { result in
				continuation.resume(with: result)
			}
		}
	}

	/// Begins remote method invocation that calls out to a Result-based completion handler.
	public func withResultCompletion<Service, Value: Sendable>(
		function: String = #function,
		on actor: isolated some Actor,
		_ body: (Service, @escaping @Sendable (Result<Value, Error>) -> Void) -> Void
	) async throws -> Value {
		try await withContinuation(function: function, on: actor) { service, continuation in
			body(service) { result in
				continuation.resume(with: result)
			}
		}
	}

	/// Begins remote method invocation that calls out to a failable completion handler.
	@_unsafeInheritExecutor
	public func withErrorCompletion<Service>(
		function: String = #function,
		_ body: (Service, @escaping @Sendable (Error?) -> Void) -> Void
	) async throws {
		try await withContinuation(function: function) { (service, continuation: CheckedContinuation<Void, Error>) in
			body(service) { error in
				if let error = error {
					continuation.resume(throwing: error)
				} else {
					continuation.resume()
				}
			}
		}
	}

	/// Begins remote method invocation that calls out to a failable completion handler.
	public func withErrorCompletion<Service>(
		function: String = #function,
		on actor: isolated some Actor,
		_ body: (Service, @escaping @Sendable (Error?) -> Void) -> Void
	) async throws {
		try await withContinuation(function: function, on: actor) { (service, continuation: CheckedContinuation<Void, Error>) in
			body(service) { error in
				if let error = error {
					continuation.resume(throwing: error)
				} else {
					continuation.resume()
				}
			}
		}
	}

	@_unsafeInheritExecutor
	public func withDecodingCompletion<Service, Value: Decodable>(
		function: String = #function,
		_ body: (Service, @escaping @Sendable (Data?, Error?) -> Void) -> Void
	) async throws -> Value {
		let data: Data = try await withValueErrorCompletion(function: function) { service, handler in
			body(service, handler)
		}

		return try JSONDecoder().decode(Value.self, from: data)
	}

	public func withDecodingCompletion<Service, Value: Decodable>(
		function: String = #function,
		on actor: isolated some Actor,
		_ body: (Service, @escaping @Sendable (Data?, Error?) -> Void) -> Void
	) async throws -> Value {
		let data: Data = try await withValueErrorCompletion(function: function, on: actor) { service, handler in
			body(service, handler)
		}

		return try JSONDecoder().decode(Value.self, from: data)
	}
}
